Workbook

Sheet DB
A1: Reference | B1: Servidor | C1: Item | D1: Categoria | E1: Sell Offer | F1: Buy Offer | G1: $ Sell Offer | H1: $ Buy Offer | I1: TC Buy | J1: TC Sell
A2: =+B2&C2 | B2: Aethera | C2: Abyssador's Lash | D2: Creature Product | G2: =IFERROR((E2/'Valor Coin por Servidor'!$B$5/250)*Conversor!$E$8,"-") | H2: =IFERROR((F2/'Valor Coin por Servidor'!$B$5/250)*Conversor!$E$8,"-") | I2: =IFERROR(_xlfn.CEILING.MATH((G2/Conversor!$E$8)*250,25),"-") | J2: =IFERROR(_xlfn.CEILING.MATH((H2/Conversor!$E$8)*250,25),"-")
A3: =+B3&C3 | B3: Aethera | C3: Alchemist's Boots | D3: Boots | G3: =IFERROR((E3/'Valor Coin por Servidor'!$B$5/250)*Conversor!$E$8,"-") | H3: =IFERROR((F3/'Valor Coin por Servidor'!$B$5/250)*Conversor!$E$8,"-") | I3: =IFERROR(_xlfn.CEILING.MATH((G3/Conversor!$E$8)*250,25),"-") | J3: =IFERROR(_xlfn.CEILING.MATH((H3/Conversor!$E$8)*250,25),"-")
A4: =+B4&C4 | B4: Aethera | C4: Alchemist's Notepad | D4: Shield | G4: =IFERROR((E4/'Valor Coin por Servidor'!$B$5/250)*Conversor!$E$8,"-") | H4: =IFERROR((F4/'Valor Coin por Servidor'!$B$5/250)*Conversor!$E$8,"-") | I4: =IFERROR(_xlfn.CEILING.MATH((G4/Conversor!$E$8)*250,25),"-") | J4: =IFERROR(_xlfn.CEILING.MATH((H4/Conversor!$E$8)*250,25),"-")
A5: =+B5&C5 | B5: Aethera | C5: Alicorn Headguard | D5: Helmet | G5: =IFERROR((E5/'Valor Coin por Servidor'!$B$5/250)*Conversor!$E$8,"-") | H5: =IFERROR((F5/'Valor Coin por Servidor'!$B$5/250)*Conversor!$E$8,"-") | I5: =IFERROR(_xlfn.CEILING.MATH((G5/Conversor!$E$8)*250,25),"-") | J5: =IFERROR(_xlfn.CEILING.MATH((H5/Conversor!$E$8)*250,25),"-")
A6: =+B6&C6 | B6: Aethera | C6: Alicorn Quiver | D6: Quiver | G6: =IFERROR((E6/'Valor Coin por Servidor'!$B$5/250)*Conversor!$E$8,"-") | H6: =IFERROR((F6/'Valor Coin por Servidor'!$B$5/250)*Conversor!$E$8,"-") | I6: =IFERROR(_xlfn.CEILING.MATH((G6/Conversor!$E$8)*250,25),"-") | J6: =IFERROR(_xlfn.CEILING.MATH((H6/Conversor!$E$8)*250,25),"-")
A7: =+B7&C7 | B7: Aethera | C7: Alicorn Ring | D7: Ring | G7: =IFERROR((E7/'Valor Coin por Servidor'!$B$5/250)*Conversor!$E$8,"-") | H7: =IFERROR((F7/'Valor Coin por Servidor'!$B$5/250)*Conversor!$E$8,"-") | I7: =IFERROR(_xlfn.CEILING.MATH((G7/Conversor!$E$8)*250,25),"-") | J7: =IFERROR(_xlfn.CEILING.MATH((H7/Conversor!$E$8)*250,25),"-")
A8: =+B8&C8 | B8: Aethera | C8: Amulet of Theurgy | D8: Amulet | G8: =IFERROR((E8/'Valor Coin por Servidor'!$B$5/250)*Conversor!$E$8,"-") | H8: =IFERROR((F8/'Valor Coin por Servidor'!$B$5/250)*Conversor!$E$8,"-") | I8: =IFERROR(_xlfn.CEILING.MATH((G8/Conversor!$E$8)*250,25),"-") | J8: =IFERROR(_xlfn.CEILING.MATH((H8/Conversor!$E$8)*250,25),"-")
A9: =+B9&C9 | B9: Aethera | C9: Antler-Horn Helmet | D9: Helmet | G9: =IFERROR((E9/'Valor Coin por Servidor'!$B$5/250)*Conversor!$E$8,"-") | H9: =IFERROR((F9/'Valor Coin por Servidor'!$B$5/250)*Conversor!$E$8,"-") | I9: =IFERROR(_xlfn.CEILING.MATH((G9/Conversor!$E$8)*250,25),"-") | J9: =IFERROR(_xlfn.CEILING.MATH((H9/Conversor!$E$8)*250,25),"-")
A10: =+B10&C10 | B10: Aethera | C10: Antlers | D10: Creature Product | G10: =IFERROR((E10/'Valor Coin por Servidor'!$B$5/250)*Conversor!$E$8,"-") | H10: =IFERROR((F10/'Valor Coin por Servidor'!$B$5/250)*Conversor!$E$8,"-") | I10: =IFERROR(_xlfn.CEILING.MATH((G10/Conversor!$E$8)*250,25),"-") | J10: =IFERROR(_xlfn.CEILING.MATH((H10/Conversor!$E$8)*250,25),"-")
A11: =+B11&C11 | B11: Aethera | C11: Ape Fur | D11: Creature Product | G11: =IFERROR((E11/'Valor Coin por Servidor'!$B$5/250)*Conversor!$E$8,"-") | H11: =IFERROR((F11/'Valor Coin por Servidor'!$B$5/250)*Conversor!$E$8,"-") | I11: =IFERROR(_xlfn.CEILING.MATH((G11/Conversor!$E$8)*250,25),"-") | J11: =IFERROR(_xlfn.CEILING.MATH((H11/Conversor!$E$8)*250,25),"-")
A12: =+B12&C12 | B12: Aethera | C12: Arboreal Crown | D12: Helmet | G12: =IFERROR((E12/'Valor Coin por Servidor'!$B$5/250)*Conversor!$E$8,"-") | H12: =IFERROR((F12/'Valor Coin por Servidor'!$B$5/250)*Conversor!$E$8,"-") | I12: =IFERROR(_xlfn.CEILING.MATH((G12/Conversor!$E$8)*250,25),"-") | J12: =IFERROR(_xlfn.CEILING.MATH((H12/Conversor!$E$8)*250,25),"-")
A13: =+B13&C13 | B13: Aethera | C13: Arboreal Ring | D13: Ring | G13: =IFERROR((E13/'Valor Coin por Servidor'!$B$5/250)*Conversor!$E$8,"-") | H13: =IFERROR((F13/'Valor Coin por Servidor'!$B$5/250)*Conversor!$E$8,"-") | I13: =IFERROR(_xlfn.CEILING.MATH((G13/Conversor!$E$8)*250,25),"-") | J13: =IFERROR(_xlfn.CEILING.MATH((H13/Conversor!$E$8)*250,25),"-")
... A315: =+B315&C315 | B315: Aethera | C315: Wyvern Talisman | D315: Creature Product | G315: =IFERROR((E315/'Valor Coin por Servidor'!$B$5/250)*Conversor!$E$8,"-") | H315: =IFERROR((F315/'Valor Coin por Servidor'!$B$5/250)*Conversor!$E$8,"-") | I315: =IFERROR(_xlfn.CEILING.MATH((G315/Conversor!$E$8)*250,25),"-") | J315: =IFERROR(_xlfn.CEILING.MATH((H315/Conversor!$E$8)*250,25),"-")
A316: =+B316&C316 | B316: Ambra | C316: Abyssador's Lash | D316: Creature Product | G316: =IFERROR((E316/'Valor Coin por Servidor'!$B$2/250)*Conversor!$E$8,"-") | H316: =IFERROR((F316/'Valor Coin por Servidor'!$B$2/250)*Conversor!$E$8,"-") | I316: =IFERROR(_xlfn.CEILING.MATH((G316/Conversor!$E$8)*250,25),"-") | J316: =IFERROR(_xlfn.CEILING.MATH((H316/Conversor!$E$8)*250,25),"-")
A317: =+B317&C317 | B317: Ambra | C317: Alchemist's Boots | D317: Boots | G317: =IFERROR((E317/'Valor Coin por Servidor'!$B$2/250)*Conversor!$E$8,"-") | H317: =IFERROR((F317/'Valor Coin por Servidor'!$B$2/250)*Conversor!$E$8,"-") | I317: =IFERROR(_xlfn.CEILING.MATH((G317/Conversor!$E$8)*250,25),"-") | J317: =IFERROR(_xlfn.CEILING.MATH((H317/Conversor!$E$8)*250,25),"-")
A318: =+B318&C318 | B318: Ambra | C318: Alchemist's Notepad | D318: Shield | G318: =IFERROR((E318/'Valor Coin por Servidor'!$B$2/250)*Conversor!$E$8,"-") | H318: =IFERROR((F318/'Valor Coin por Servidor'!$B$2/250)*Conversor!$E$8,"-") | I318: =IFERROR(_xlfn.CEILING.MATH((G318/Conversor!$E$8)*250,25),"-") | J318: =IFERROR(_xlfn.CEILING.MATH((H318/Conversor!$E$8)*250,25),"-")
A319: =+B319&C319 | B319: Ambra | C319: Alicorn Headguard | D319: Helmet | G319: =IFERROR((E319/'Valor Coin por Servidor'!$B$2/250)*Conversor!$E$8,"-") | H319: =IFERROR((F319/'Valor Coin por Servidor'!$B$2/250)*Conversor!$E$8,"-") | I319: =IFERROR(_xlfn.CEILING.MATH((G319/Conversor!$E$8)*250,25),"-") | J319: =IFERROR(_xlfn.CEILING.MATH((H319/Conversor!$E$8)*250,25),"-")
A320: =+B320&C320 | B320: Ambra | C320: Alicorn Quiver | D320: Quiver | G320: =IFERROR((E320/'Valor Coin por Servidor'!$B$2/250)*Conversor!$E$8,"-") | H320: =IFERROR((F320/'Valor Coin por Servidor'!$B$2/250)*Conversor!$E$8,"-") | I320: =IFERROR(_xlfn.CEILING.MATH((G320/Conversor!$E$8)*250,25),"-") | J320: =IFERROR(_xlfn.CEILING.MATH((H320/Conversor!$E$8)*250,25),"-")
A321: =+B321&C321 | B321: Ambra | C321: Alicorn Ring | D321: Ring | G321: =IFERROR((E321/'Valor Coin por Servidor'!$B$2/250)*Conversor!$E$8,"-") | H321: =IFERROR((F321/'Valor Coin por Servidor'!$B$2/250)*Conversor!$E$8,"-") | I321: =IFERROR(_xlfn.CEILING.MATH((G321/Conversor!$E$8)*250,25),"-") | J321: =IFERROR(_xlfn.CEILING.MATH((H321/Conversor!$E$8)*250,25),"-")
A322: =+B322&C322 | B322: Ambra | C322: Amulet of Theurgy | D322: Amulet | G322: =IFERROR((E322/'Valor Coin por Servidor'!$B$2/250)*Conversor!$E$8,"-") | H322: =IFERROR((F322/'Valor Coin por Servidor'!$B$2/250)*Conversor!$E$8,"-") | I322: =IFERROR(_xlfn.CEILING.MATH((G322/Conversor!$E$8)*250,25),"-") | J322: =IFERROR(_xlfn.CEILING.MATH((H322/Conversor!$E$8)*250,25),"-")
A323: =+B323&C323 | B323: Ambra | C323: Antler-Horn Helmet | D323: Helmet | G323: =IFERROR((E323/'Valor Coin por Servidor'!$B$2/250)*Conversor!$E$8,"-") | H323: =IFERROR((F323/'Valor Coin por Servidor'!$B$2/250)*Conversor!$E$8,"-") | I323: =IFERROR(_xlfn.CEILING.MATH((G323/Conversor!$E$8)*250,25),"-") | J323: =IFERROR(_xlfn.CEILING.MATH((H323/Conversor!$E$8)*250,25),"-")
A324: =+B324&C324 | B324: Ambra | C324: Antlers | D324: Creature Product | G324: =IFERROR((E324/'Valor Coin por Servidor'!$B$2/250)*Conversor!$E$8,"-") | H324: =IFERROR((F324/'Valor Coin por Servidor'!$B$2/250)*Conversor!$E$8,"-") | I324: =IFERROR(_xlfn.CEILING.MATH((G324/Conversor!$E$8)*250,25),"-") | J324: =IFERROR(_xlfn.CEILING.MATH((H324/Conversor!$E$8)*250,25),"-")
A325: =+B325&C325 | B325: Ambra | C325: Ape Fur | D325: Creature Product | G325: =IFERROR((E325/'Valor Coin por Servidor'!$B$2/250)*Conversor!$E$8,"-") | H325: =IFERROR((F325/'Valor Coin por Servidor'!$B$2/250)*Conversor!$E$8,"-") | I325: =IFERROR(_xlfn.CEILING.MATH((G325/Conversor!$E$8)*250,25),"-") | J325: =IFERROR(_xlfn.CEILING.MATH((H325/Conversor!$E$8)*250,25),"-")
A326: =+B326&C326 | B326: Ambra | C326: Arboreal Crown | D326: Helmet | G326: =IFERROR((E326/'Valor Coin por Servidor'!$B$2/250)*Conversor!$E$8,"-") | H326: =IFERROR((F326/'Valor Coin por Servidor'!$B$2/250)*Conversor!$E$8,"-") | I326: =IFERROR(_xlfn.CEILING.MATH((G326/Conversor!$E$8)*250,25),"-") | J326: =IFERROR(_xlfn.CEILING.MATH((H326/Conversor!$E$8)*250,25),"-")
A327: =+B327&C327 | B327: Ambra | C327: Arboreal Ring | D327: Ring | G327: =IFERROR((E327/'Valor Coin por Servidor'!$B$2/250)*Conversor!$E$8,"-") | H327: =IFERROR((F327/'Valor Coin por Servidor'!$B$2/250)*Conversor!$E$8,"-") | I327: =IFERROR(_xlfn.CEILING.MATH((G327/Conversor!$E$8)*250,25),"-") | J327: =IFERROR(_xlfn.CEILING.MATH((H327/Conversor!$E$8)*250,25),"-")
... A629: =+B629&C629 | B629: Ambra | C629: Wyvern Talisman | D629: Creature Product | G629: =IFERROR((E629/'Valor Coin por Servidor'!$B$2/250)*Conversor!$E$8,"-") | H629: =IFERROR((F629/'Valor Coin por Servidor'!$B$2/250)*Conversor!$E$8,"-") | I629: =IFERROR(_xlfn.CEILING.MATH((G629/Conversor!$E$8)*250,25),"-") | J629: =IFERROR(_xlfn.CEILING.MATH((H629/Conversor!$E$8)*250,25),"-")
A630: =+B630&C630 | B630: Antica | C630: Abyssador's Lash | D630: Creature Product | G630: =IFERROR((E630/'Valor Coin por Servidor'!$B$3/250)*Conversor!$E$8,"-") | H630: =IFERROR((F630/'Valor Coin por Servidor'!$B$3/250)*Conversor!$E$8,"-") | I630: =IFERROR(_xlfn.CEILING.MATH((G630/Conversor!$E$8)*250,25),"-") | J630: =IFERROR(_xlfn.CEILING.MATH((H630/Conversor!$E$8)*250,25),"-")
A631: =+B631&C631 | B631: Antica | C631: Alchemist's Boots | D631: Boots | G631: =IFERROR((E631/'Valor Coin por Servidor'!$B$3/250)*Conversor!$E$8,"-") | H631: =IFERROR((F631/'Valor Coin por Servidor'!$B$3/250)*Conversor!$E$8,"-") | I631: =IFERROR(_xlfn.CEILING.MATH((G631/Conversor!$E$8)*250,25),"-") | J631: =IFERROR(_xlfn.CEILING.MATH((H631/Conversor!$E$8)*250,25),"-")
A632: =+B632&C632 | B632: Antica | C632: Alchemist's Notepad | D632: Shield | G632: =IFERROR((E632/'Valor Coin por Servidor'!$B$3/250)*Conversor!$E$8,"-") | H632: =IFERROR((F632/'Valor Coin por Servidor'!$B$3/250)*Conversor!$E$8,"-") | I632: =IFERROR(_xlfn.CEILING.MATH((G632/Conversor!$E$8)*250,25),"-") | J632: =IFERROR(_xlfn.CEILING.MATH((H632/Conversor!$E$8)*250,25),"-")
A633: =+B633&C633 | B633: Antica | C633: Alicorn Headguard | D633: Helmet | G633: =IFERROR((E633/'Valor Coin por Servidor'!$B$3/250)*Conversor!$E$8,"-") | H633: =IFERROR((F633/'Valor Coin por Servidor'!$B$3/250)*Conversor!$E$8,"-") | I633: =IFERROR(_xlfn.CEILING.MATH((G633/Conversor!$E$8)*250,25),"-") | J633: =IFERROR(_xlfn.CEILING.MATH((H633/Conversor!$E$8)*250,25),"-")
A634: =+B634&C634 | B634: Antica | C634: Alicorn Quiver | D634: Quiver | G634: =IFERROR((E634/'Valor Coin por Servidor'!$B$3/250)*Conversor!$E$8,"-") | H634: =IFERROR((F634/'Valor Coin por Servidor'!$B$3/250)*Conversor!$E$8,"-") | I634: =IFERROR(_xlfn.CEILING.MATH((G634/Conversor!$E$8)*250,25),"-") | J634: =IFERROR(_xlfn.CEILING.MATH((H634/Conversor!$E$8)*250,25),"-")
A635: =+B635&C635 | B635: Antica | C635: Alicorn Ring | D635: Ring | G635: =IFERROR((E635/'Valor Coin por Servidor'!$B$3/250)*Conversor!$E$8,"-") | H635: =IFERROR((F635/'Valor Coin por Servidor'!$B$3/250)*Conversor!$E$8,"-") | I635: =IFERROR(_xlfn.CEILING.MATH((G635/Conversor!$E$8)*250,25),"-") | J635: =IFERROR(_xlfn.CEILING.MATH((H635/Conversor!$E$8)*250,25),"-")
A636: =+B636&C636 | B636: Antica | C636: Amulet of Theurgy | D636: Amulet | G636: =IFERROR((E636/'Valor Coin por Servidor'!$B$3/250)*Conversor!$E$8,"-") | H636: =IFERROR((F636/'Valor Coin por Servidor'!$B$3/250)*Conversor!$E$8,"-") | I636: =IFERROR(_xlfn.CEILING.MATH((G636/Conversor!$E$8)*250,25),"-") | J636: =IFERROR(_xlfn.CEILING.MATH((H636/Conversor!$E$8)*250,25),"-")
A637: =+B637&C637 | B637: Antica | C637: Antler-Horn Helmet | D637: Helmet | G637: =IFERROR((E637/'Valor Coin por Servidor'!$B$3/250)*Conversor!$E$8,"-") | H637: =IFERROR((F637/'Valor Coin por Servidor'!$B$3/250)*Conversor!$E$8,"-") | I637: =IFERROR(_xlfn.CEILING.MATH((G637/Conversor!$E$8)*250,25),"-") | J637: =IFERROR(_xlfn.CEILING.MATH((H637/Conversor!$E$8)*250,25),"-")
A638: =+B638&C638 | B638: Antica | C638: Antlers | D638: Creature Product | G638: =IFERROR((E638/'Valor Coin por Servidor'!$B$3/250)*Conversor!$E$8,"-") | H638: =IFERROR((F638/'Valor Coin por Servidor'!$B$3/250)*Conversor!$E$8,"-") | I638: =IFERROR(_xlfn.CEILING.MATH((G638/Conversor!$E$8)*250,25),"-") | J638: =IFERROR(_xlfn.CEILING.MATH((H638/Conversor!$E$8)*250,25),"-")
A639: =+B639&C639 | B639: Antica | C639: Ape Fur | D639: Creature Product | G639: =IFERROR((E639/'Valor Coin por Servidor'!$B$3/250)*Conversor!$E$8,"-") | H639: =IFERROR((F639/'Valor Coin por Servidor'!$B$3/250)*Conversor!$E$8,"-") | I639: =IFERROR(_xlfn.CEILING.MATH((G639/Conversor!$E$8)*250,25),"-") | J639: =IFERROR(_xlfn.CEILING.MATH((H639/Conversor!$E$8)*250,25),"-")
A640: =+B640&C640 | B640: Antica | C640: Arboreal Crown | D640: Helmet | G640: =IFERROR((E640/'Valor Coin por Servidor'!$B$3/250)*Conversor!$E$8,"-") | H640: =IFERROR((F640/'Valor Coin por Servidor'!$B$3/250)*Conversor!$E$8,"-") | I640: =IFERROR(_xlfn.CEILING.MATH((G640/Conversor!$E$8)*250,25),"-") | J640: =IFERROR(_xlfn.CEILING.MATH((H640/Conversor!$E$8)*250,25),"-")
A641: =+B641&C641 | B641: Antica | C641: Arboreal Ring | D641: Ring | G641: =IFERROR((E641/'Valor Coin por Servidor'!$B$3/250)*Conversor!$E$8,"-") | H641: =IFERROR((F641/'Valor Coin por Servidor'!$B$3/250)*Conversor!$E$8,"-") | I641: =IFERROR(_xlfn.CEILING.MATH((G641/Conversor!$E$8)*250,25),"-") | J641: =IFERROR(_xlfn.CEILING.MATH((H641/Conversor!$E$8)*250,25),"-")
... A943: =+B943&C943 | B943: Antica | C943: Wyvern Talisman | D943: Creature Product | G943: =IFERROR((E943/'Valor Coin por Servidor'!$B$3/250)*Conversor!$E$8,"-") | H943: =IFERROR((F943/'Valor Coin por Servidor'!$B$3/250)*Conversor!$E$8,"-") | I943: =IFERROR(_xlfn.CEILING.MATH((G943/Conversor!$E$8)*250,25),"-") | J943: =IFERROR(_xlfn.CEILING.MATH((H943/Conversor!$E$8)*250,25),"-")
...
